Workbook

Sheet Resumo Executivo
A1: RELATORIO GERENCIAL · CONTAS A PAGAR
A2: AP Aging — Agosto 2026 | T2: cat | U2: val
A3: ="Posicao em "&TEXT(Parametros!$B$6,"DD/MM/YYYY")&" - Fonte: SAP - Administrar itens fornecedor (partidas em aberto)" | T3: Construction Services – Under Litigation | U3: =ABS(SUMIF('Aging por Categoria'!$A$5:$A$21,$T3,'Aging por Categoria'!$I$5:$I$21)) | X3: =TEXT(I8/1000000,"#,##0.0")&"M"&CHAR(10)&"Total Terceiros"
T4: Operational Suppliers (Wind Farms) | U4: =ABS(SUMIF('Aging por Categoria'!$A$5:$A$21,$T4,'Aging por Categoria'!$I$5:$I$21))
T5: Customs Brokerage – Overall | U5: =ABS(SUMIF('Aging por Categoria'!$A$5:$A$21,$T5,'Aging por Categoria'!$I$5:$I$21))
T6: SINOMA | U6: =ABS(SUMIF('Aging por Categoria'!$A$5:$A$21,$T6,'Aging por Categoria'!$I$5:$I$21))
A7: EXPOSICAO TOTAL | E7: INTERCOMPANY | I7: TERCEIROS | M7: VENCIDO | T7: Other Suppliers | U7: =ABS(SUMIF('Aging por Categoria'!$A$5:$A$21,$T7,'Aging por Categoria'!$I$5:$I$21))
A8: =ABS('Aging por Categoria'!$I$22) | E8: =ABS(SUMIF('Aging por Categoria'!$A$5:$A$21,"Intercompany",'Aging por Categoria'!$I$5:$I$21)) | I8: =ABS('Aging por Categoria'!$I$22-SUMIF('Aging por Categoria'!$A$5:$A$21,"Intercompany",'Aging por Categoria'!$I$5:$I$21)) | M8: =ABS(SUMIF(Base[Vencido],1,Base[Montante])) | T8: Demais categorias | U8: =MAX(0,ABS('Aging por Categoria'!I22-SUMIF('Aging por Categoria'!$A$5:$A$21,"Intercompany",'Aging por Categoria'!$I$5:$I$21))-(U3+U4+U5+U6+U7))
A9: Saldo consolidado na data de corte | E9: Empresas do grupo Nordex | I9: Fornecedores externos | M9: Vencimento ja expirado
T12: ano | U12: val
T13: Até 2020 | U13: =ABS('Aging por Categoria'!B22) | V13: =AVERAGE($U$13:$U$19) | X13: =TEXT(ABS('Aging por Categoria'!H22/1000000),"#,##0.0")&"M"&CHAR(10)&"Saldo 2026"
T14: 2021 | U14: =ABS('Aging por Categoria'!C22) | V14: =AVERAGE($U$13:$U$19)
T15: 2022 | U15: =ABS('Aging por Categoria'!D22) | V15: =AVERAGE($U$13:$U$19)
T16: 2023 | U16: =ABS('Aging por Categoria'!E22) | V16: =AVERAGE($U$13:$U$19)
T17: 2024 | U17: =ABS('Aging por Categoria'!F22) | V17: =AVERAGE($U$13:$U$19)
T18: 2025 | U18: =ABS('Aging por Categoria'!G22) | V18: =AVERAGE($U$13:$U$19)
T19: 2026 | U19: =ABS('Aging por Categoria'!H22) | V19: =AVERAGE($U$13:$U$19)
T22: forn | U22: val
T23: 4U CONSTRUCOES LTDA EPP | U23: =ABS(SUMIF(Base[Fornecedor],"101963",Base[Montante]))
T24: SINOMA WIND POWER BLADE (BRAZIL) LT | U24: =ABS(SUMIF(Base[Fornecedor],"103849",Base[Montante]))
T25: 3Z MOVIMENTACAO INTELIGENTE LTDA 94 | U25: =ABS(SUMIF(Base[Fornecedor],"102113",Base[Montante]))
T26: TRADEWORKS SERVICOS DE COMERCIO EXT | U26: =ABS(SUMIF(Base[Fornecedor],"105984",Base[Montante]))
T27: CUSTOM COMERCIO INTERNACIONAL LTDA | U27: =ABS(SUMIF(Base[Fornecedor],"101071",Base[Montante]))
T28: DARCY PACHECO SOLUCOES DE PESO LTDA | U28: =ABS(SUMIF(Base[Fornecedor],"101801",Base[Montante]))
T29: ZURICH MINAS BRASIL SEGUROS S A | U29: =ABS(SUMIF(Base[Fornecedor],"101463",Base[Montante]))

Sheet Base
A1: Conta | B1: Fornecedor | C1: Nome do fornecedor | D1: Tipo doc | E1: Documento | F1: Referência | G1: Moeda | H1: Montante | I1: Data documento | J1: Data vencimento | K1: Texto | L1: Atribuição | M1: Ano | N1: Categoria | O1: Dias atraso | P1: Vencido
A2: 2122100000 | B2: IC1000 | C2: NORDEX ENERGY SE & CO KG | D2: AB | E2: 1008418 | G2: EUR | H2: 33462.83 | I2: 45227 | J2: 45227 | K2: Clearing document NORDEX ENERGY SE & CO. KG | L2: 403000.NORDENER | M2: =IF(YEAR(I2)<=2020,"Até 2020",TEXT(YEAR(I2),"0")) | N2: =IFERROR(INDEX(DePara!$A:$A,MATCH(TEXT(B2,"0"),DePara!$D:$D,0)),"(sem categoria)") | O2: =IF(J2="","",Parametros!$B$6-J2) | P2: =IF(O2="","",IF(O2>0,1,0))
A3: 2122100000 | B3: IC4420 | C3: NORDEX ENERGY SPAIN S A U | D3: AB | E3: 1008419 | G3: EUR | H3: 93546.45 | I3: 45227 | J3: 45227 | K3: Clearing document NORDEX ENERGY SPAIN S.A.U. | L3: intercompany | M3: =IF(YEAR(I3)<=2020,"Até 2020",TEXT(YEAR(I3),"0")) | N3: =IFERROR(INDEX(DePara!$A:$A,MATCH(TEXT(B3,"0"),DePara!$D:$D,0)),"(sem categoria)") | O3: =IF(J3="","",Parametros!$B$6-J3) | P3: =IF(O3="","",IF(O3>0,1,0))
A4: 2122100000 | B4: IC4420 | C4: NORDEX ENERGY SPAIN S A U | D4: AB | E4: 1008419 | G4: EUR | H4: 63508.45 | I4: 45227 | J4: 45227 | K4: Clearing document NORDEX ENERGY SPAIN S.A.U. | L4: intercompany | M4: =IF(YEAR(I4)<=2020,"Até 2020",TEXT(YEAR(I4),"0")) | N4: =IFERROR(INDEX(DePara!$A:$A,MATCH(TEXT(B4,"0"),DePara!$D:$D,0)),"(sem categoria)") | O4: =IF(J4="","",Parametros!$B$6-J4) | P4: =IF(O4="","",IF(O4>0,1,0))
A5: 2122100000 | B5: IC4420 | C5: NORDEX ENERGY SPAIN S A U | D5: RE | E5: 5000001 | F5: 4025008482 | G5: EUR | H5: -181492.25 | I5: 45964 | J5: 45994 | K5: 0846/25 | L5: 4025008482 | M5: =IF(YEAR(I5)<=2020,"Até 2020",TEXT(YEAR(I5),"0")) | N5: =IFERROR(INDEX(DePara!$A:$A,MATCH(TEXT(B5,"0"),DePara!$D:$D,0)),"(sem categoria)") | O5: =IF(J5="","",Parametros!$B$6-J5) | P5: =IF(O5="","",IF(O5>0,1,0))
A6: 2122100000 | B6: IC4420 | C6: NORDEX ENERGY SPAIN S A U | D6: RE | E6: 5000003 | F6: 4025008480 | G6: EUR | H6: -95934.74 | I6: 45964 | J6: 45994 | K6: 0842/25 | L6: 4025008480 | M6: =IF(YEAR(I6)<=2020,"Até 2020",TEXT(YEAR(I6),"0")) | N6: =IFERROR(INDEX(DePara!$A:$A,MATCH(TEXT(B6,"0"),DePara!$D:$D,0)),"(sem categoria)") | O6: =IF(J6="","",Parametros!$B$6-J6) | P6: =IF(O6="","",IF(O6>0,1,0))
A7: 2122100000 | B7: IC4420 | C7: NORDEX ENERGY SPAIN S A U | D7: RE | E7: 5000005 | F7: 4025008261 | G7: EUR | H7: -251289.79 | I7: 45957 | J7: 45987 | K7: 0826/25 | L7: 4025008261 | M7: =IF(YEAR(I7)<=2020,"Até 2020",TEXT(YEAR(I7),"0")) | N7: =IFERROR(INDEX(DePara!$A:$A,MATCH(TEXT(B7,"0"),DePara!$D:$D,0)),"(sem categoria)") | O7: =IF(J7="","",Parametros!$B$6-J7) | P7: =IF(O7="","",IF(O7>0,1,0))
A8: 2122100000 | B8: IC4420 | C8: NORDEX ENERGY SPAIN S A U | D8: RE | E8: 5000072 | F8: 4025008229 | G8: EUR | H8: -3838623.1 | I8: 45954 | J8: 45984 | K8: 0852/25 | L8: 4025008229 | M8: =IF(YEAR(I8)<=2020,"Até 2020",TEXT(YEAR(I8),"0")) | N8: =IFERROR(INDEX(DePara!$A:$A,MATCH(TEXT(B8,"0"),DePara!$D:$D,0)),"(sem categoria)") | O8: =IF(J8="","",Parametros!$B$6-J8) | P8: =IF(O8="","",IF(O8>0,1,0))
A9: 2122100000 | B9: IC4420 | C9: NORDEX ENERGY SPAIN S A U | D9: RE | E9: 5000180 | F9: 4025008478 | G9: EUR | H9: -1330.48 | I9: 45964 | J9: 45994 | K9: 0844/25 | L9: 4025008478 | M9: =IF(YEAR(I9)<=2020,"Até 2020",TEXT(YEAR(I9),"0")) | N9: =IFERROR(INDEX(DePara!$A:$A,MATCH(TEXT(B9,"0"),DePara!$D:$D,0)),"(sem categoria)") | O9: =IF(J9="","",Parametros!$B$6-J9) | P9: =IF(O9="","",IF(O9>0,1,0))
A10: 2122100000 | B10: IC4420 | C10: NORDEX ENERGY SPAIN S A U | D10: RE | E10: 5000181 | F10: 4025008476 | G10: EUR | H10: -118914.41 | I10: 45964 | J10: 45994 | K10: 0844/25 | L10: 4025008476 | M10: =IF(YEAR(I10)<=2020,"Até 2020",TEXT(YEAR(I10),"0")) | N10: =IFERROR(INDEX(DePara!$A:$A,MATCH(TEXT(B10,"0"),DePara!$D:$D,0)),"(sem categoria)") | O10: =IF(J10="","",Parametros!$B$6-J10) | P10: =IF(O10="","",IF(O10>0,1,0))
A11: 2122100000 | B11: IC4420 | C11: NORDEX ENERGY SPAIN S A U | D11: RE | E11: 5000188 | F11: 4025009533 | G11: EUR | H11: -2357 | I11: 46000 | J11: 46030 | K11: 0926/25 | L11: 4025009533 | M11: =IF(YEAR(I11)<=2020,"Até 2020",TEXT(YEAR(I11),"0")) | N11: =IFERROR(INDEX(DePara!$A:$A,MATCH(TEXT(B11,"0"),DePara!$D:$D,0)),"(sem categoria)") | O11: =IF(J11="","",Parametros!$B$6-J11) | P11: =IF(O11="","",IF(O11>0,1,0))
A12: 2122100000 | B12: IC4420 | C12: NORDEX ENERGY SPAIN S A U | D12: RE | E12: 5000190 | F12: 4025009569 | G12: EUR | H12: -6504.31 | I12: 46001 | J12: 46031 | K12: 0921/25 | L12: 4025009569 | M12: =IF(YEAR(I12)<=2020,"Até 2020",TEXT(YEAR(I12),"0")) | N12: =IFERROR(INDEX(DePara!$A:$A,MATCH(TEXT(B12,"0"),DePara!$D:$D,0)),"(sem categoria)") | O12: =IF(J12="","",Parametros!$B$6-J12) | P12: =IF(O12="","",IF(O12>0,1,0))
A13: 2122100000 | B13: IC4420 | C13: NORDEX ENERGY SPAIN S A U | D13: RE | E13: 5000236 | F13: 4025009111 | G13: EUR | H13: -826.41 | I13: 45987 | J13: 46017 | K13: 0890/25 | L13: 4025009111 | M13: =IF(YEAR(I13)<=2020,"Até 2020",TEXT(YEAR(I13),"0")) | N13: =IFERROR(INDEX(DePara!$A:$A,MATCH(TEXT(B13,"0"),DePara!$D:$D,0)),"(sem categoria)") | O13: =IF(J13="","",Parametros!$B$6-J13) | P13: =IF(O13="","",IF(O13>0,1,0))
A14: 2122100000 | B14: IC4420 | C14: NORDEX ENERGY SPAIN S A U | D14: RE | E14: 5000246 | F14: 4025008477 | G14: EUR | H14: -9145.39 | I14: 45964 | J14: 45994 | K14: 0845/25 | L14: 4025008477 | M14: =IF(YEAR(I14)<=2020,"Até 2020",TEXT(YEAR(I14),"0")) | N14: =IFERROR(INDEX(DePara!$A:$A,MATCH(TEXT(B14,"0"),DePara!$D:$D,0)),"(sem categoria)") | O14: =IF(J14="","",Parametros!$B$6-J14) | P14: =IF(O14="","",IF(O14>0,1,0))
A15: 2122100000 | B15: IC4420 | C15: NORDEX ENERGY SPAIN S A U | D15: RE | E15: 5000263 | F15: 4025008479 | G15: EUR | H15: -193802.69 | I15: 45964 | J15: 45994 | K15: 0843/25 | L15: 4025008479 | M15: =IF(YEAR(I15)<=2020,"Até 2020",TEXT(YEAR(I15),"0")) | N15: =IFERROR(INDEX(DePara!$A:$A,MATCH(TEXT(B15,"0"),DePara!$D:$D,0)),"(sem categoria)") | O15: =IF(J15="","",Parametros!$B$6-J15) | P15: =IF(O15="","",IF(O15>0,1,0))
A16: 2122100000 | B16: IC4420 | C16: NORDEX ENERGY SPAIN S A U | D16: RE | E16: 5000284 | F16: 4025009104 | G16: EUR | H16: -33691.24 | I16: 45987 | J16: 46017 | K16: 0908/25 | L16: 4025009104 | M16: =IF(YEAR(I16)<=2020,"Até 2020",TEXT(YEAR(I16),"0")) | N16: =IFERROR(INDEX(DePara!$A:$A,MATCH(TEXT(B16,"0"),DePara!$D:$D,0)),"(sem categoria)") | O16: =IF(J16="","",Parametros!$B$6-J16) | P16: =IF(O16="","",IF(O16>0,1,0))
... A69: 2122100000 | B69: IC4420 | C69: NORDEX ENERGY SPAIN S A U | D69: RE | E69: 5001704 | F69: 4025010003 | G69: EUR | H69: -32587.47 | I69: 46020 | J69: 46050 | K69: 0010/26 | L69: 4025010003 | M69: =IF(YEAR(I69)<=2020,"Até 2020",TEXT(YEAR(I69),"0")) | N69: =IFERROR(INDEX(DePara!$A:$A,MATCH(TEXT(B69,"0"),DePara!$D:$D,0)),"(sem categoria)") | O69: =IF(J69="","",Parametros!$B$6-J69) | P69: =IF(O69="","",IF(O69>0,1,0))
A70: 2122100000 | B70: IC4420 | C70: NORDEX ENERGY SPAIN S A U | D70: KG | E70: 5001799 | F70: 4000013 | G70: EUR | H70: 4427773.7 | I70: 46044 | J70: 46044 | K70: Nota crédito fornec. NORDEX ENERGY SPAIN S A U 400 | M70: =IF(YEAR(I70)<=2020,"Até 2020",TEXT(YEAR(I70),"0")) | N70: =IFERROR(INDEX(DePara!$A:$A,MATCH(TEXT(B70,"0"),DePara!$D:$D,0)),"(sem categoria)") | O70: =IF(J70="","",Parametros!$B$6-J70) | P70: =IF(O70="","",IF(O70>0,1,0))
A71: 2122100000 | B71: IC4420 | C71: NORDEX ENERGY SPAIN S A U | D71: RE | E71: 5001827 | F71: 4026000050 | G71: EUR | H71: -4187.65 | I71: 46029 | J71: 46059 | K71: 0016/26 | L71: 4026000050 | M71: =IF(YEAR(I71)<=2020,"Até 2020",TEXT(YEAR(I71),"0")) | N71: =IFERROR(INDEX(DePara!$A:$A,MATCH(TEXT(B71,"0"),DePara!$D:$D,0)),"(sem categoria)") | O71: =IF(J71="","",Parametros!$B$6-J71) | P71: =IF(O71="","",IF(O71>0,1,0))
A72: 2122100000 | B72: IC4420 | C72: NORDEX ENERGY SPAIN S A U | D72: RE | E72: 5001828 | F72: 4026000027 | G72: EUR | H72: -12947.14 | I72: 46027 | J72: 46057 | K72: 0015/26 | L72: 4026000027 | M72: =IF(YEAR(I72)<=2020,"Até 2020",TEXT(YEAR(I72),"0")) | N72: =IFERROR(INDEX(DePara!$A:$A,MATCH(TEXT(B72,"0"),DePara!$D:$D,0)),"(sem categoria)") | O72: =IF(J72="","",Parametros!$B$6-J72) | P72: =IF(O72="","",IF(O72>0,1,0))
A73: 2122100000 | B73: IC4420 | C73: NORDEX ENERGY SPAIN S A U | D73: RE | E73: 5001829 | F73: 4026000051 | G73: EUR | H73: -259.39 | I73: 46029 | J73: 46059 | K73: 0016/26 | L73: 4026000051 | M73: =IF(YEAR(I73)<=2020,"Até 2020",TEXT(YEAR(I73),"0")) | N73: =IFERROR(INDEX(DePara!$A:$A,MATCH(TEXT(B73,"0"),DePara!$D:$D,0)),"(sem categoria)") | O73: =IF(J73="","",Parametros!$B$6-J73) | P73: =IF(O73="","",IF(O73>0,1,0))
A74: 2122100000 | B74: IC1000 | C74: NORDEX ENERGY SE & CO KG | D74: KR | E74: 5001865 | F74: 624366 | G74: EUR | H74: -63754.33 | I74: 46042 | J74: 46072 | K74: Vendor Invoice NORDEX ENERGY SE & CO KG 624366 | M74: =IF(YEAR(I74)<=2020,"Até 2020",TEXT(YEAR(I74),"0")) | N74: =IFERROR(INDEX(DePara!$A:$A,MATCH(TEXT(B74,"0"),DePara!$D:$D,0)),"(sem categoria)") | O74: =IF(J74="","",Parametros!$B$6-J74) | P74: =IF(O74="","",IF(O74>0,1,0))
A75: 2122100000 | B75: IC4420 | C75: NORDEX ENERGY SPAIN S A U | D75: RE | E75: 5001935 | F75: 4026000283 | G75: EUR | H75: -15956.51 | I75: 46036 | J75: 46066 | K75: 0025/26 | L75: 4026000283 | M75: =IF(YEAR(I75)<=2020,"Até 2020",TEXT(YEAR(I75),"0")) | N75: =IFERROR(INDEX(DePara!$A:$A,MATCH(TEXT(B75,"0"),DePara!$D:$D,0)),"(sem categoria)") | O75: =IF(J75="","",Parametros!$B$6-J75) | P75: =IF(O75="","",IF(O75>0,1,0))
A76: 2122100000 | B76: IC4420 | C76: NORDEX ENERGY SPAIN S A U | D76: RE | E76: 5001937 | F76: 4026000285 | G76: EUR | H76: -5.72 | I76: 46036 | J76: 46066 | K76: 0027/26 | L76: 4026000285 | M76: =IF(YEAR(I76)<=2020,"Até 2020",TEXT(YEAR(I76),"0")) | N76: =IFERROR(INDEX(DePara!$A:$A,MATCH(TEXT(B76,"0"),DePara!$D:$D,0)),"(sem categoria)") | O76: =IF(J76="","",Parametros!$B$6-J76) | P76: =IF(O76="","",IF(O76>0,1,0))
A77: 2122100000 | B77: IC4420 | C77: NORDEX ENERGY SPAIN S A U | D77: RE | E77: 5001974 | F77: 4025007233 | G77: EUR | H77: -2632.09 | I77: 45919 | J77: 45949 | K77: 0782/25 | L77: 4025007233 | M77: =IF(YEAR(I77)<=2020,"Até 2020",TEXT(YEAR(I77),"0")) | N77: =IFERROR(INDEX(DePara!$A:$A,MATCH(TEXT(B77,"0"),DePara!$D:$D,0)),"(sem categoria)") | O77: =IF(J77="","",Parametros!$B$6-J77) | P77: =IF(O77="","",IF(O77>0,1,0))
A78: 2122100000 | B78: IC4420 | C78: NORDEX ENERGY SPAIN S A U | D78: RE | E78: 5001999 | F78: 4025007248 | G78: EUR | H78: -168218.94 | I78: 45919 | J78: 45949 | K78: 0777/25 | L78: 4025007248 | M78: =IF(YEAR(I78)<=2020,"Até 2020",TEXT(YEAR(I78),"0")) | N78: =IFERROR(INDEX(DePara!$A:$A,MATCH(TEXT(B78,"0"),DePara!$D:$D,0)),"(sem categoria)") | O78: =IF(J78="","",Parametros!$B$6-J78) | P78: =IF(O78="","",IF(O78>0,1,0))
A79: 2122100000 | B79: IC4420 | C79: NORDEX ENERGY SPAIN S A U | D79: RE | E79: 5002000 | F79: 4025007244 | G79: EUR | H79: -51550.43 | I79: 45919 | J79: 45949 | K79: 0780/25 | L79: 4025007244 | M79: =IF(YEAR(I79)<=2020,"Até 2020",TEXT(YEAR(I79),"0")) | N79: =IFERROR(INDEX(DePara!$A:$A,MATCH(TEXT(B79,"0"),DePara!$D:$D,0)),"(sem categoria)") | O79: =IF(J79="","",Parametros!$B$6-J79) | P79: =IF(O79="","",IF(O79>0,1,0))
A80: 2122100000 | B80: IC1000 | C80: NORDEX ENERGY SE & CO KG | D80: RE | E80: 5002045 | F80: 4012485638 | G80: BRL | H80: -5367090.2 | I80: 45965 | J80: 45995 | K80: 0911/25 | L80: 4012485638 | M80: =IF(YEAR(I80)<=2020,"Até 2020",TEXT(YEAR(I80),"0")) | N80: =IFERROR(INDEX(DePara!$A:$A,MATCH(TEXT(B80,"0"),DePara!$D:$D,0)),"(sem categoria)") | O80: =IF(J80="","",Parametros!$B$6-J80) | P80: =IF(O80="","",IF(O80>0,1,0))
A81: 2122100000 | B81: IC4420 | C81: NORDEX ENERGY SPAIN S A U | D81: KR | E81: 5002054 | F81: 4023004386 | G81: EUR | H81: -200.59 | I81: 45191 | J81: 45191 | K81: Vendor Invoice NORDEX ENERGY SPAIN S.A.U. 40230043 | M81: =IF(YEAR(I81)<=2020,"Até 2020",TEXT(YEAR(I81),"0")) | N81: =IFERROR(INDEX(DePara!$A:$A,MATCH(TEXT(B81,"0"),DePara!$D:$D,0)),"(sem categoria)") | O81: =IF(J81="","",Parametros!$B$6-J81) | P81: =IF(O81="","",IF(O81>0,1,0))
A82: 2122100000 | B82: IC4420 | C82: NORDEX ENERGY SPAIN S A U | D82: RE | E82: 5002129 | F82: 1957-2 | G82: EUR | H82: -19466.82 | I82: 45166 | J82: 45226 | K82: Fatura - bruto NORDEX ENERGY SPAIN S.A.U. 1957-2 | M82: =IF(YEAR(I82)<=2020,"Até 2020",TEXT(YEAR(I82),"0")) | N82: =IFERROR(INDEX(DePara!$A:$A,MATCH(TEXT(B82,"0"),DePara!$D:$D,0)),"(sem categoria)") | O82: =IF(J82="","",Parametros!$B$6-J82) | P82: =IF(O82="","",IF(O82>0,1,0))
A83: 2122100000 | B83: IC1000 | C83: NORDEX ENERGY SE & CO KG | D83: RE | E83: 5002142 | F83: 4082412983 | G83: EUR | H83: -43259.58 | I83: 45607 | J83: 45637 | K83: 1035/24 | L83: 4082412983 | M83: =IF(YEAR(I83)<=2020,"Até 2020",TEXT(YEAR(I83),"0")) | N83: =IFERROR(INDEX(DePara!$A:$A,MATCH(TEXT(B83,"0"),DePara!$D:$D,0)),"(sem categoria)") | O83: =IF(J83="","",Parametros!$B$6-J83) | P83: =IF(O83="","",IF(O83>0,1,0))
A84: 2122100000 | B84: IC4420 | C84: NORDEX ENERGY SPAIN S A U | D84: RE | E84: 5002175 | F84: 4025008713 | G84: EUR | H84: -257530.17 | I84: 45973 | J84: 46003 | K84: 0869/25 | L84: 4025008713 | M84: =IF(YEAR(I84)<=2020,"Até 2020",TEXT(YEAR(I84),"0")) | N84: =IFERROR(INDEX(DePara!$A:$A,MATCH(TEXT(B84,"0"),DePara!$D:$D,0)),"(sem categoria)") | O84: =IF(J84="","",Parametros!$B$6-J84) | P84: =IF(O84="","",IF(O84>0,1,0))
A85: 2122100000 | B85: IC4420 | C85: NORDEX ENERGY SPAIN S A U | D85: RE | E85: 5002296 | F85: 4025009096 | G85: EUR | H85: -380499.92 | I85: 45987 | J85: 46017 | K85: 0891/25 | L85: 4025009096 | M85: =IF(YEAR(I85)<=2020,"Até 2020",TEXT(YEAR(I85),"0")) | N85: =IFERROR(INDEX(DePara!$A:$A,MATCH(TEXT(B85,"0"),DePara!$D:$D,0)),"(sem categoria)") | O85: =IF(J85="","",Parametros!$B$6-J85) | P85: =IF(O85="","",IF(O85>0,1,0))
A86: 2122100000 | B86: IC1000 | C86: NORDEX ENERGY SE & CO KG | D86: RE | E86: 5002302 | F86: 4012338641 | G86: EUR | H86: -20000.82 | I86: 45092 | J86: 45122 | K86: 0463/23 | L86: 4012338641 | M86: =IF(YEAR(I86)<=2020,"Até 2020",TEXT(YEAR(I86),"0")) | N86: =IFERROR(INDEX(DePara!$A:$A,MATCH(TEXT(B86,"0"),DePara!$D:$D,0)),"(sem categoria)") | O86: =IF(J86="","",Parametros!$B$6-J86) | P86: =IF(O86="","",IF(O86>0,1,0))
A87: 2122100000 | B87: IC1000 | C87: NORDEX ENERGY SE & CO KG | D87: RE | E87: 5002304 | F87: 4012338640 | G87: EUR | H87: -115262.57 | I87: 45092 | J87: 45122 | K87: 0463/23 | L87: 4012338640 | M87: =IF(YEAR(I87)<=2020,"Até 2020",TEXT(YEAR(I87),"0")) | N87: =IFERROR(INDEX(DePara!$A:$A,MATCH(TEXT(B87,"0"),DePara!$D:$D,0)),"(sem categoria)") | O87: =IF(J87="","",Parametros!$B$6-J87) | P87: =IF(O87="","",IF(O87>0,1,0))
A88: 2122100000 | B88: IC1000 | C88: NORDEX ENERGY SE & CO KG | D88: RE | E88: 5002310 | F88: 4012338638 | G88: EUR | H88: -84910.62 | I88: 45092 | J88: 45122 | K88: 0463/23 | L88: 4012338638 | M88: =IF(YEAR(I88)<=2020,"Até 2020",TEXT(YEAR(I88),"0")) | N88: =IFERROR(INDEX(DePara!$A:$A,MATCH(TEXT(B88,"0"),DePara!$D:$D,0)),"(sem categoria)") | O88: =IF(J88="","",Parametros!$B$6-J88) | P88: =IF(O88="","",IF(O88>0,1,0))
A89: 2122100000 | B89: IC1000 | C89: NORDEX ENERGY SE & CO KG | D89: RE | E89: 5002312 | F89: 4012338639 | G89: EUR | H89: -45435.7 | I89: 45092 | J89: 45122 | K89: 0463/23 | L89: 4012338639 | M89: =IF(YEAR(I89)<=2020,"Até 2020",TEXT(YEAR(I89),"0")) | N89: =IFERROR(INDEX(DePara!$A:$A,MATCH(TEXT(B89,"0"),DePara!$D:$D,0)),"(sem categoria)") | O89: =IF(J89="","",Parametros!$B$6-J89) | P89: =IF(O89="","",IF(O89>0,1,0))
A90: 2122100000 | B90: IC1000 | C90: NORDEX ENERGY SE & CO KG | D90: RE | E90: 5002313 | F90: 4012343664 | G90: EUR | H90: -367068.34 | I90: 45097 | J90: 45127 | K90: 0543/23 | L90: 4012343664 | M90: =IF(YEAR(I90)<=2020,"Até 2020",TEXT(YEAR(I90),"0")) | N90: =IFERROR(INDEX(DePara!$A:$A,MATCH(TEXT(B90,"0"),DePara!$D:$D,0)),"(sem categoria)") | O90: =IF(J90="","",Parametros!$B$6-J90) | P90: =IF(O90="","",IF(O90>0,1,0))
A91: 2122100000 | B91: IC4420 | C91: NORDEX ENERGY SPAIN S A U | D91: RE | E91: 5002394 | F91: 4026000275 | G91: EUR | H91: -9662.37 | I91: 46035 | J91: 46065 | K91: 0019/26 | L91: 4026000275 | M91: =IF(YEAR(I91)<=2020,"Até 2020",TEXT(YEAR(I91),"0")) | N91: =IFERROR(INDEX(DePara!$A:$A,MATCH(TEXT(B91,"0"),DePara!$D:$D,0)),"(sem categoria)") | O91: =IF(J91="","",Parametros!$B$6-J91) | P91: =IF(O91="","",IF(O91>0,1,0))
A92: 2122100000 | B92: IC1000 | C92: NORDEX ENERGY SE & CO KG | D92: RE | E92: 5002523 | F92: 4012413022 | G92: EUR | H92: -959152.94 | I92: 45490 | J92: 45520 | K92: 0941/24 | L92: 4012413022 | M92: =IF(YEAR(I92)<=2020,"Até 2020",TEXT(YEAR(I92),"0")) | N92: =IFERROR(INDEX(DePara!$A:$A,MATCH(TEXT(B92,"0"),DePara!$D:$D,0)),"(sem categoria)") | O92: =IF(J92="","",Parametros!$B$6-J92) | P92: =IF(O92="","",IF(O92>0,1,0))
...

Sheet DePara
A1: Categoria | B1: Nome do fornecedor | C1: Fornecedor | D1: Fornecedor_txt
A2: Other Suppliers | C2: 100002 | D2: 100002
A3: Other Suppliers | C3: 100003 | D3: 100003
A4: Operational Suppliers (Wind Farms) | C4: 100007 | D4: 100007
A5: Other Suppliers | B5: DB3 SERVICOS DE TELECOMUNICACOES SA | C5: 100008 | D5: 100008
A6: Other Suppliers | B6: TRANSITEX DO BRASIL SERVIÇOS DE LO | C6: 100014 | D6: 100014
A7: Other Suppliers | B7: HOST TECNOLOGIA LTDA | C7: 100018 | D7: 100018
A8: Operational Suppliers (Wind Farms) | B8: PAIVA SERVICOS LTDA | C8: 100026 | D8: 100026
A9: Customs Brokerage – Overall | B9: SUPPLOG PORTO SECO DE IPOJUCA LTDA | C9: 100028 | D9: 100028
A10: Operational Suppliers (Wind Farms) | B10: MEGAWIND INDUSTRIA E COMERCIO | C10: 100031 | D10: 100031
A11: Other Suppliers | C11: 100032 | D11: 100032
A12: Customs Brokerage – Overall | B12: EMBRAPORT EMPRESA BRASILEIRA DE TER | C12: 100036 | D12: 100036
A13: Other Suppliers | C13: 100039 | D13: 100039
A14: Operational Suppliers (Wind Farms) | C14: 100041 | D14: 100041
A15: Other Suppliers | C15: 100049 | D15: 100049
A16: Customs Brokerage – Overall | C16: 100051 | D16: 100051
A17: Other Suppliers | C17: 100094 | D17: 100094
A18: Operational Suppliers (Wind Farms) | C18: 100095 | D18: 100095
A19: Other Suppliers | C19: 100097 | D19: 100097
A20: Other Suppliers | B20: PRESENCA COMERCIAL LTDA | C20: 100099 | D20: 100099
A21: Operational Suppliers (Wind Farms) | C21: 100102 | D21: 100102
A22: Operational Suppliers (Wind Farms) | C22: 100110 | D22: 100110
A23: Other Suppliers | B23: PREDMEC ENGENHARIA DE MANUTENCAO E | C23: 100111 | D23: 100111
A24: Other Suppliers | B24: PERMETAL S A METAIS PERFURADOS | C24: 100124 | D24: 100124
A25: Other Suppliers | B25: LENGUAE LANGUAGE SERVICES LTDA | C25: 100128 | D25: 100128
A26: Other Suppliers | B26: ULTRATECH MONTAGEM E MANUTENCAO LTD | C26: 100149 | D26: 100149
A27: Other Suppliers | B27: CONQUER HOLDING EDUCACIONAL SA | C27: 100152 | D27: 100152
A28: Other Suppliers | B28: CAMARA DE COM E IND BRASIL ALEMANHA | C28: 100161 | D28: 100161
A29: Operational Suppliers (Wind Farms) | C29: 100177 | D29: 100177
A30: Other Suppliers | C30: 100182 | D30: 100182
A31: Customs Brokerage – Overall | B31: AGL TRANSPORTES INTERNACIONAIS LTDA | C31: 100183 | D31: 100183
A32: Other Suppliers | B32: EPHARMA PBM DO BRASIL SA | C32: 100192 | D32: 100192
A33: Other Suppliers | C33: 100194 | D33: 100194
A34: Operational Suppliers (Wind Farms) | C34: 100200 | D34: 100200
A35: Other Suppliers | C35: 100204 | D35: 100204
A36: Other Suppliers | C36: 100206 | D36: 100206
A37: Operational Suppliers (Wind Farms) | C37: 100346 | D37: 100346
A38: LDs Service Payments | C38: 100353 | D38: 100353
A39: Operational Suppliers (Wind Farms) | C39: 100355 | D39: 100355
A40: Other Suppliers | B40: INOVAR LOCACOES MOSSORO LTDA | C40: 100359 | D40: 100359
...

Sheet Parametros
A1: CONFIGURACAO
A2: Parametros da base
A3: Definicoes de extracao e conferencia do relatorio
A5: Empresa | B5: 4690 — Nordex Energy Brasil LTDA
A6: Data de corte | B6: 46265
A7: Relatorio-fonte | B7: Administrar itens fornecedor (SAP Fiori)
A8: Criterio de extracao | B8: Partidas em aberto | Aberto na data fixada = data de corte | Itens normais + Transacoes do Razao Especial
A9: Eixo de envelhecimento | B9: Idade do documento contabil de origem
A11: RECONCILIACAO
A12: Total da base | B12: =SUM(Base[Montante])
A13: Total de conferencia (Razao) | B13: -1.2027407e+09
A14: Diferenca | B14: =B12-B13

Sheet Aging por Categoria
A1: AP AGING
A2: Exposicao por categoria
A3: Envelhecimento pela idade do documento contabil de origem
A4: Categoria | B4: Até 2020 | C4: 2021 | D4: 2022 | E4: 2023 | F4: 2024 | G4: 2025 | H4: 2026 | I4: Total
A5: Construction Services – Under Litigation | B5: =SUMIFS(Base[Montante],Base[Categoria],$A5,Base[Ano],B$4) | C5: =SUMIFS(Base[Montante],Base[Categoria],$A5,Base[Ano],C$4) | D5: =SUMIFS(Base[Montante],Base[Categoria],$A5,Base[Ano],D$4) | E5: =SUMIFS(Base[Montante],Base[Categoria],$A5,Base[Ano],E$4) | F5: =SUMIFS(Base[Montante],Base[Categoria],$A5,Base[Ano],F$4) | G5: =SUMIFS(Base[Montante],Base[Categoria],$A5,Base[Ano],G$4) | H5: =SUMIFS(Base[Montante],Base[Categoria],$A5,Base[Ano],H$4) | I5: =SUM(B5:H5)
A6: Aeris | B6: =SUMIFS(Base[Montante],Base[Categoria],$A6,Base[Ano],B$4) | C6: =SUMIFS(Base[Montante],Base[Categoria],$A6,Base[Ano],C$4) | D6: =SUMIFS(Base[Montante],Base[Categoria],$A6,Base[Ano],D$4) | E6: =SUMIFS(Base[Montante],Base[Categoria],$A6,Base[Ano],E$4) | F6: =SUMIFS(Base[Montante],Base[Categoria],$A6,Base[Ano],F$4) | G6: =SUMIFS(Base[Montante],Base[Categoria],$A6,Base[Ano],G$4) | H6: =SUMIFS(Base[Montante],Base[Categoria],$A6,Base[Ano],H$4) | I6: =SUM(B6:H6)
A7: Consumables Suppliers | B7: =SUMIFS(Base[Montante],Base[Categoria],$A7,Base[Ano],B$4) | C7: =SUMIFS(Base[Montante],Base[Categoria],$A7,Base[Ano],C$4) | D7: =SUMIFS(Base[Montante],Base[Categoria],$A7,Base[Ano],D$4) | E7: =SUMIFS(Base[Montante],Base[Categoria],$A7,Base[Ano],E$4) | F7: =SUMIFS(Base[Montante],Base[Categoria],$A7,Base[Ano],F$4) | G7: =SUMIFS(Base[Montante],Base[Categoria],$A7,Base[Ano],G$4) | H7: =SUMIFS(Base[Montante],Base[Categoria],$A7,Base[Ano],H$4) | I7: =SUM(B7:H7)
A8: Customs Brokerage – Overall | B8: =SUMIFS(Base[Montante],Base[Categoria],$A8,Base[Ano],B$4) | C8: =SUMIFS(Base[Montante],Base[Categoria],$A8,Base[Ano],C$4) | D8: =SUMIFS(Base[Montante],Base[Categoria],$A8,Base[Ano],D$4) | E8: =SUMIFS(Base[Montante],Base[Categoria],$A8,Base[Ano],E$4) | F8: =SUMIFS(Base[Montante],Base[Categoria],$A8,Base[Ano],F$4) | G8: =SUMIFS(Base[Montante],Base[Categoria],$A8,Base[Ano],G$4) | H8: =SUMIFS(Base[Montante],Base[Categoria],$A8,Base[Ano],H$4) | I8: =SUM(B8:H8)
A9: Corporate Card Payments | B9: =SUMIFS(Base[Montante],Base[Categoria],$A9,Base[Ano],B$4) | C9: =SUMIFS(Base[Montante],Base[Categoria],$A9,Base[Ano],C$4) | D9: =SUMIFS(Base[Montante],Base[Categoria],$A9,Base[Ano],D$4) | E9: =SUMIFS(Base[Montante],Base[Categoria],$A9,Base[Ano],E$4) | F9: =SUMIFS(Base[Montante],Base[Categoria],$A9,Base[Ano],F$4) | G9: =SUMIFS(Base[Montante],Base[Categoria],$A9,Base[Ano],G$4) | H9: =SUMIFS(Base[Montante],Base[Categoria],$A9,Base[Ano],H$4) | I9: =SUM(B9:H9)
A10: Facilities | B10: =SUMIFS(Base[Montante],Base[Categoria],$A10,Base[Ano],B$4) | C10: =SUMIFS(Base[Montante],Base[Categoria],$A10,Base[Ano],C$4) | D10: =SUMIFS(Base[Montante],Base[Categoria],$A10,Base[Ano],D$4) | E10: =SUMIFS(Base[Montante],Base[Categoria],$A10,Base[Ano],E$4) | F10: =SUMIFS(Base[Montante],Base[Categoria],$A10,Base[Ano],F$4) | G10: =SUMIFS(Base[Montante],Base[Categoria],$A10,Base[Ano],G$4) | H10: =SUMIFS(Base[Montante],Base[Categoria],$A10,Base[Ano],H$4) | I10: =SUM(B10:H10)
A11: Insurance | B11: =SUMIFS(Base[Montante],Base[Categoria],$A11,Base[Ano],B$4) | C11: =SUMIFS(Base[Montante],Base[Categoria],$A11,Base[Ano],C$4) | D11: =SUMIFS(Base[Montante],Base[Categoria],$A11,Base[Ano],D$4) | E11: =SUMIFS(Base[Montante],Base[Categoria],$A11,Base[Ano],E$4) | F11: =SUMIFS(Base[Montante],Base[Categoria],$A11,Base[Ano],F$4) | G11: =SUMIFS(Base[Montante],Base[Categoria],$A11,Base[Ano],G$4) | H11: =SUMIFS(Base[Montante],Base[Categoria],$A11,Base[Ano],H$4) | I11: =SUM(B11:H11)
A12: Intercompany | B12: =SUMIFS(Base[Montante],Base[Categoria],$A12,Base[Ano],B$4) | C12: =SUMIFS(Base[Montante],Base[Categoria],$A12,Base[Ano],C$4) | D12: =SUMIFS(Base[Montante],Base[Categoria],$A12,Base[Ano],D$4) | E12: =SUMIFS(Base[Montante],Base[Categoria],$A12,Base[Ano],E$4) | F12: =SUMIFS(Base[Montante],Base[Categoria],$A12,Base[Ano],F$4) | G12: =SUMIFS(Base[Montante],Base[Categoria],$A12,Base[Ano],G$4) | H12: =SUMIFS(Base[Montante],Base[Categoria],$A12,Base[Ano],H$4) | I12: =SUM(B12:H12)
A13: Legal Services Suppliers | B13: =SUMIFS(Base[Montante],Base[Categoria],$A13,Base[Ano],B$4) | C13: =SUMIFS(Base[Montante],Base[Categoria],$A13,Base[Ano],C$4) | D13: =SUMIFS(Base[Montante],Base[Categoria],$A13,Base[Ano],D$4) | E13: =SUMIFS(Base[Montante],Base[Categoria],$A13,Base[Ano],E$4) | F13: =SUMIFS(Base[Montante],Base[Categoria],$A13,Base[Ano],F$4) | G13: =SUMIFS(Base[Montante],Base[Categoria],$A13,Base[Ano],G$4) | H13: =SUMIFS(Base[Montante],Base[Categoria],$A13,Base[Ano],H$4) | I13: =SUM(B13:H13)
A14: Nordex Employees | B14: =SUMIFS(Base[Montante],Base[Categoria],$A14,Base[Ano],B$4) | C14: =SUMIFS(Base[Montante],Base[Categoria],$A14,Base[Ano],C$4) | D14: =SUMIFS(Base[Montante],Base[Categoria],$A14,Base[Ano],D$4) | E14: =SUMIFS(Base[Montante],Base[Categoria],$A14,Base[Ano],E$4) | F14: =SUMIFS(Base[Montante],Base[Categoria],$A14,Base[Ano],F$4) | G14: =SUMIFS(Base[Montante],Base[Categoria],$A14,Base[Ano],G$4) | H14: =SUMIFS(Base[Montante],Base[Categoria],$A14,Base[Ano],H$4) | I14: =SUM(B14:H14)
A15: Operational Suppliers (Wind Farms) | B15: =SUMIFS(Base[Montante],Base[Categoria],$A15,Base[Ano],B$4) | C15: =SUMIFS(Base[Montante],Base[Categoria],$A15,Base[Ano],C$4) | D15: =SUMIFS(Base[Montante],Base[Categoria],$A15,Base[Ano],D$4) | E15: =SUMIFS(Base[Montante],Base[Categoria],$A15,Base[Ano],E$4) | F15: =SUMIFS(Base[Montante],Base[Categoria],$A15,Base[Ano],F$4) | G15: =SUMIFS(Base[Montante],Base[Categoria],$A15,Base[Ano],G$4) | H15: =SUMIFS(Base[Montante],Base[Categoria],$A15,Base[Ano],H$4) | I15: =SUM(B15:H15)
A16: Other Suppliers | B16: =SUMIFS(Base[Montante],Base[Categoria],$A16,Base[Ano],B$4) | C16: =SUMIFS(Base[Montante],Base[Categoria],$A16,Base[Ano],C$4) | D16: =SUMIFS(Base[Montante],Base[Categoria],$A16,Base[Ano],D$4) | E16: =SUMIFS(Base[Montante],Base[Categoria],$A16,Base[Ano],E$4) | F16: =SUMIFS(Base[Montante],Base[Categoria],$A16,Base[Ano],F$4) | G16: =SUMIFS(Base[Montante],Base[Categoria],$A16,Base[Ano],G$4) | H16: =SUMIFS(Base[Montante],Base[Categoria],$A16,Base[Ano],H$4) | I16: =SUM(B16:H16)
... A21: (sem categoria) | B21: =SUMIFS(Base[Montante],Base[Categoria],$A21,Base[Ano],B$4) | C21: =SUMIFS(Base[Montante],Base[Categoria],$A21,Base[Ano],C$4) | D21: =SUMIFS(Base[Montante],Base[Categoria],$A21,Base[Ano],D$4) | E21: =SUMIFS(Base[Montante],Base[Categoria],$A21,Base[Ano],E$4) | F21: =SUMIFS(Base[Montante],Base[Categoria],$A21,Base[Ano],F$4) | G21: =SUMIFS(Base[Montante],Base[Categoria],$A21,Base[Ano],G$4) | H21: =SUMIFS(Base[Montante],Base[Categoria],$A21,Base[Ano],H$4) | I21: =SUM(B21:H21)
A22: Total geral | B22: =SUM(B5:B21) | C22: =SUM(C5:C21) | D22: =SUM(D5:D21) | E22: =SUM(E5:E21) | F22: =SUM(F5:F21) | G22: =SUM(G5:G21) | H22: =SUM(H5:H21) | I22: =SUM(I5:I21)

Sheet Aging por Conta
A1: AP AGING
A2: Exposicao por conta contabil
A3: Envelhecimento pela idade do documento contabil de origem
A4: Conta | B4: Descricao | C4: Até 2020 | D4: 2021 | E4: 2022 | F4: 2023 | G4: 2024 | H4: 2025 | I4: 2026 | J4: Total
A5: 1000010000 | B5: FUNDO FIXO DE CAIXA | C5: =SUMIFS(Base[Montante],Base[Conta],$A5,Base[Ano],C$4) | D5: =SUMIFS(Base[Montante],Base[Conta],$A5,Base[Ano],D$4) | E5: =SUMIFS(Base[Montante],Base[Conta],$A5,Base[Ano],E$4) | F5: =SUMIFS(Base[Montante],Base[Conta],$A5,Base[Ano],F$4) | G5: =SUMIFS(Base[Montante],Base[Conta],$A5,Base[Ano],G$4) | H5: =SUMIFS(Base[Montante],Base[Conta],$A5,Base[Ano],H$4) | I5: =SUMIFS(Base[Montante],Base[Conta],$A5,Base[Ano],I$4) | J5: =SUM(C5:I5)
A6: 1117730000 | B6: ADIANTAMENTO DE VIAGENS | C6: =SUMIFS(Base[Montante],Base[Conta],$A6,Base[Ano],C$4) | D6: =SUMIFS(Base[Montante],Base[Conta],$A6,Base[Ano],D$4) | E6: =SUMIFS(Base[Montante],Base[Conta],$A6,Base[Ano],E$4) | F6: =SUMIFS(Base[Montante],Base[Conta],$A6,Base[Ano],F$4) | G6: =SUMIFS(Base[Montante],Base[Conta],$A6,Base[Ano],G$4) | H6: =SUMIFS(Base[Montante],Base[Conta],$A6,Base[Ano],H$4) | I6: =SUMIFS(Base[Montante],Base[Conta],$A6,Base[Ano],I$4) | J6: =SUM(C6:I6)
A7: 1191000000 | B7: ADIANT. FORNECEDORES - TERCEIROS | C7: =SUMIFS(Base[Montante],Base[Conta],$A7,Base[Ano],C$4) | D7: =SUMIFS(Base[Montante],Base[Conta],$A7,Base[Ano],D$4) | E7: =SUMIFS(Base[Montante],Base[Conta],$A7,Base[Ano],E$4) | F7: =SUMIFS(Base[Montante],Base[Conta],$A7,Base[Ano],F$4) | G7: =SUMIFS(Base[Montante],Base[Conta],$A7,Base[Ano],G$4) | H7: =SUMIFS(Base[Montante],Base[Conta],$A7,Base[Ano],H$4) | I7: =SUMIFS(Base[Montante],Base[Conta],$A7,Base[Ano],I$4) | J7: =SUM(C7:I7)
A8: 1193100000 | B8: ADIANT. FORNECEDORES - PARTES RELACIONADAS | C8: =SUMIFS(Base[Montante],Base[Conta],$A8,Base[Ano],C$4) | D8: =SUMIFS(Base[Montante],Base[Conta],$A8,Base[Ano],D$4) | E8: =SUMIFS(Base[Montante],Base[Conta],$A8,Base[Ano],E$4) | F8: =SUMIFS(Base[Montante],Base[Conta],$A8,Base[Ano],F$4) | G8: =SUMIFS(Base[Montante],Base[Conta],$A8,Base[Ano],G$4) | H8: =SUMIFS(Base[Montante],Base[Conta],$A8,Base[Ano],H$4) | I8: =SUMIFS(Base[Montante],Base[Conta],$A8,Base[Ano],I$4) | J8: =SUM(C8:I8)
A9: 1517730000 | B9: ADIANTAMENTO DE VIAGEM | C9: =SUMIFS(Base[Montante],Base[Conta],$A9,Base[Ano],C$4) | D9: =SUMIFS(Base[Montante],Base[Conta],$A9,Base[Ano],D$4) | E9: =SUMIFS(Base[Montante],Base[Conta],$A9,Base[Ano],E$4) | F9: =SUMIFS(Base[Montante],Base[Conta],$A9,Base[Ano],F$4) | G9: =SUMIFS(Base[Montante],Base[Conta],$A9,Base[Ano],G$4) | H9: =SUMIFS(Base[Montante],Base[Conta],$A9,Base[Ano],H$4) | I9: =SUMIFS(Base[Montante],Base[Conta],$A9,Base[Ano],I$4) | J9: =SUM(C9:I9)
A10: 2111000000 | B10: FORNECEDORES NACIONAIS | C10: =SUMIFS(Base[Montante],Base[Conta],$A10,Base[Ano],C$4) | D10: =SUMIFS(Base[Montante],Base[Conta],$A10,Base[Ano],D$4) | E10: =SUMIFS(Base[Montante],Base[Conta],$A10,Base[Ano],E$4) | F10: =SUMIFS(Base[Montante],Base[Conta],$A10,Base[Ano],F$4) | G10: =SUMIFS(Base[Montante],Base[Conta],$A10,Base[Ano],G$4) | H10: =SUMIFS(Base[Montante],Base[Conta],$A10,Base[Ano],H$4) | I10: =SUMIFS(Base[Montante],Base[Conta],$A10,Base[Ano],I$4) | J10: =SUM(C10:I10)
A11: 2112000000 | B11: CONTAS A PAGAR - PAISES ESTRANGEIROS | C11: =SUMIFS(Base[Montante],Base[Conta],$A11,Base[Ano],C$4) | D11: =SUMIFS(Base[Montante],Base[Conta],$A11,Base[Ano],D$4) | E11: =SUMIFS(Base[Montante],Base[Conta],$A11,Base[Ano],E$4) | F11: =SUMIFS(Base[Montante],Base[Conta],$A11,Base[Ano],F$4) | G11: =SUMIFS(Base[Montante],Base[Conta],$A11,Base[Ano],G$4) | H11: =SUMIFS(Base[Montante],Base[Conta],$A11,Base[Ano],H$4) | I11: =SUMIFS(Base[Montante],Base[Conta],$A11,Base[Ano],I$4) | J11: =SUM(C11:I11)
A12: 2114340000 | B12: RESPONSABILIDADES COM EMPREGADOS | C12: =SUMIFS(Base[Montante],Base[Conta],$A12,Base[Ano],C$4) | D12: =SUMIFS(Base[Montante],Base[Conta],$A12,Base[Ano],D$4) | E12: =SUMIFS(Base[Montante],Base[Conta],$A12,Base[Ano],E$4) | F12: =SUMIFS(Base[Montante],Base[Conta],$A12,Base[Ano],F$4) | G12: =SUMIFS(Base[Montante],Base[Conta],$A12,Base[Ano],G$4) | H12: =SUMIFS(Base[Montante],Base[Conta],$A12,Base[Ano],H$4) | I12: =SUMIFS(Base[Montante],Base[Conta],$A12,Base[Ano],I$4) | J12: =SUM(C12:I12)
A13: 2122100000 | B13: FORNECEDORES - PARTES RELACIONADAS | C13: =SUMIFS(Base[Montante],Base[Conta],$A13,Base[Ano],C$4) | D13: =SUMIFS(Base[Montante],Base[Conta],$A13,Base[Ano],D$4) | E13: =SUMIFS(Base[Montante],Base[Conta],$A13,Base[Ano],E$4) | F13: =SUMIFS(Base[Montante],Base[Conta],$A13,Base[Ano],F$4) | G13: =SUMIFS(Base[Montante],Base[Conta],$A13,Base[Ano],G$4) | H13: =SUMIFS(Base[Montante],Base[Conta],$A13,Base[Ano],H$4) | I13: =SUMIFS(Base[Montante],Base[Conta],$A13,Base[Ano],I$4) | J13: =SUM(C13:I13)
A14: Total geral | C14: =SUM(C5:C13) | D14: =SUM(D5:D13) | E14: =SUM(E5:E13) | F14: =SUM(F5:F13) | G14: =SUM(G5:G13) | H14: =SUM(H5:H13) | I14: =SUM(I5:I13) | J14: =SUM(J5:J13)

Sheet Posição por Fornecedor
A1: AP AGING
A2: Posicao por fornecedor
A3: Filtre pela coluna Categoria ou Fornecedor usando as setas do cabecalho
A4: Fornecedor | B4: Nome do fornecedor | C4: Categoria | D4: Até 2020 | E4: 2021 | F4: 2022 | G4: 2023 | H4: 2024 | I4: 2025 | J4: 2026 | K4: Total
A5: 114597 | B5: BLUEWAY TRADING IMPORTAÇAO E EXPORT SA | C5: =IFERROR(INDEX(DePara[Categoria],MATCH(TEXT(A5,"0"),DePara[Fornecedor_txt],0)),"(sem categoria)") | D5: =SUMIFS(Base[Montante],Base[Fornecedor],$A5&"",Base[Ano],D$4) | E5: =SUMIFS(Base[Montante],Base[Fornecedor],$A5&"",Base[Ano],E$4) | F5: =SUMIFS(Base[Montante],Base[Fornecedor],$A5&"",Base[Ano],F$4) | G5: =SUMIFS(Base[Montante],Base[Fornecedor],$A5&"",Base[Ano],G$4) | H5: =SUMIFS(Base[Montante],Base[Fornecedor],$A5&"",Base[Ano],H$4) | I5: =SUMIFS(Base[Montante],Base[Fornecedor],$A5&"",Base[Ano],I$4) | J5: =SUMIFS(Base[Montante],Base[Fornecedor],$A5&"",Base[Ano],J$4) | K5: =SUM(D5:J5)
A6: 115019 | B6: BLUEWAY TRADING IMPORTAÇAO E EXPORT SA | C6: =IFERROR(INDEX(DePara[Categoria],MATCH(TEXT(A6,"0"),DePara[Fornecedor_txt],0)),"(sem categoria)") | D6: =SUMIFS(Base[Montante],Base[Fornecedor],$A6&"",Base[Ano],D$4) | E6: =SUMIFS(Base[Montante],Base[Fornecedor],$A6&"",Base[Ano],E$4) | F6: =SUMIFS(Base[Montante],Base[Fornecedor],$A6&"",Base[Ano],F$4) | G6: =SUMIFS(Base[Montante],Base[Fornecedor],$A6&"",Base[Ano],G$4) | H6: =SUMIFS(Base[Montante],Base[Fornecedor],$A6&"",Base[Ano],H$4) | I6: =SUMIFS(Base[Montante],Base[Fornecedor],$A6&"",Base[Ano],I$4) | J6: =SUMIFS(Base[Montante],Base[Fornecedor],$A6&"",Base[Ano],J$4) | K6: =SUM(D6:J6)
A7: 100446 | B7: DSV AIR & SEA BRASIL LTDA | C7: =IFERROR(INDEX(DePara[Categoria],MATCH(TEXT(A7,"0"),DePara[Fornecedor_txt],0)),"(sem categoria)") | D7: =SUMIFS(Base[Montante],Base[Fornecedor],$A7&"",Base[Ano],D$4) | E7: =SUMIFS(Base[Montante],Base[Fornecedor],$A7&"",Base[Ano],E$4) | F7: =SUMIFS(Base[Montante],Base[Fornecedor],$A7&"",Base[Ano],F$4) | G7: =SUMIFS(Base[Montante],Base[Fornecedor],$A7&"",Base[Ano],G$4) | H7: =SUMIFS(Base[Montante],Base[Fornecedor],$A7&"",Base[Ano],H$4) | I7: =SUMIFS(Base[Montante],Base[Fornecedor],$A7&"",Base[Ano],I$4) | J7: =SUMIFS(Base[Montante],Base[Fornecedor],$A7&"",Base[Ano],J$4) | K7: =SUM(D7:J7)
A8: 100447 | B8: DSV AIR & SEA BRASIL LTDA | C8: =IFERROR(INDEX(DePara[Categoria],MATCH(TEXT(A8,"0"),DePara[Fornecedor_txt],0)),"(sem categoria)") | D8: =SUMIFS(Base[Montante],Base[Fornecedor],$A8&"",Base[Ano],D$4) | E8: =SUMIFS(Base[Montante],Base[Fornecedor],$A8&"",Base[Ano],E$4) | F8: =SUMIFS(Base[Montante],Base[Fornecedor],$A8&"",Base[Ano],F$4) | G8: =SUMIFS(Base[Montante],Base[Fornecedor],$A8&"",Base[Ano],G$4) | H8: =SUMIFS(Base[Montante],Base[Fornecedor],$A8&"",Base[Ano],H$4) | I8: =SUMIFS(Base[Montante],Base[Fornecedor],$A8&"",Base[Ano],I$4) | J8: =SUMIFS(Base[Montante],Base[Fornecedor],$A8&"",Base[Ano],J$4) | K8: =SUM(D8:J8)
A9: 100805 | B9: EXPRESSO VALE REAL LTDA | C9: =IFERROR(INDEX(DePara[Categoria],MATCH(TEXT(A9,"0"),DePara[Fornecedor_txt],0)),"(sem categoria)") | D9: =SUMIFS(Base[Montante],Base[Fornecedor],$A9&"",Base[Ano],D$4) | E9: =SUMIFS(Base[Montante],Base[Fornecedor],$A9&"",Base[Ano],E$4) | F9: =SUMIFS(Base[Montante],Base[Fornecedor],$A9&"",Base[Ano],F$4) | G9: =SUMIFS(Base[Montante],Base[Fornecedor],$A9&"",Base[Ano],G$4) | H9: =SUMIFS(Base[Montante],Base[Fornecedor],$A9&"",Base[Ano],H$4) | I9: =SUMIFS(Base[Montante],Base[Fornecedor],$A9&"",Base[Ano],I$4) | J9: =SUMIFS(Base[Montante],Base[Fornecedor],$A9&"",Base[Ano],J$4) | K9: =SUM(D9:J9)
A10: 100830 | B10: EXPRESSO VALE REAL LTDA | C10: =IFERROR(INDEX(DePara[Categoria],MATCH(TEXT(A10,"0"),DePara[Fornecedor_txt],0)),"(sem categoria)") | D10: =SUMIFS(Base[Montante],Base[Fornecedor],$A10&"",Base[Ano],D$4) | E10: =SUMIFS(Base[Montante],Base[Fornecedor],$A10&"",Base[Ano],E$4) | F10: =SUMIFS(Base[Montante],Base[Fornecedor],$A10&"",Base[Ano],F$4) | G10: =SUMIFS(Base[Montante],Base[Fornecedor],$A10&"",Base[Ano],G$4) | H10: =SUMIFS(Base[Montante],Base[Fornecedor],$A10&"",Base[Ano],H$4) | I10: =SUMIFS(Base[Montante],Base[Fornecedor],$A10&"",Base[Ano],I$4) | J10: =SUMIFS(Base[Montante],Base[Fornecedor],$A10&"",Base[Ano],J$4) | K10: =SUM(D10:J10)
A11: 100929 | B11: EXPRESSO VALE REAL LTDA | C11: =IFERROR(INDEX(DePara[Categoria],MATCH(TEXT(A11,"0"),DePara[Fornecedor_txt],0)),"(sem categoria)") | D11: =SUMIFS(Base[Montante],Base[Fornecedor],$A11&"",Base[Ano],D$4) | E11: =SUMIFS(Base[Montante],Base[Fornecedor],$A11&"",Base[Ano],E$4) | F11: =SUMIFS(Base[Montante],Base[Fornecedor],$A11&"",Base[Ano],F$4) | G11: =SUMIFS(Base[Montante],Base[Fornecedor],$A11&"",Base[Ano],G$4) | H11: =SUMIFS(Base[Montante],Base[Fornecedor],$A11&"",Base[Ano],H$4) | I11: =SUMIFS(Base[Montante],Base[Fornecedor],$A11&"",Base[Ano],I$4) | J11: =SUMIFS(Base[Montante],Base[Fornecedor],$A11&"",Base[Ano],J$4) | K11: =SUM(D11:J11)
A12: 100573 | B12: FEDERAL EXPRESS CORPORATION | C12: =IFERROR(INDEX(DePara[Categoria],MATCH(TEXT(A12,"0"),DePara[Fornecedor_txt],0)),"(sem categoria)") | D12: =SUMIFS(Base[Montante],Base[Fornecedor],$A12&"",Base[Ano],D$4) | E12: =SUMIFS(Base[Montante],Base[Fornecedor],$A12&"",Base[Ano],E$4) | F12: =SUMIFS(Base[Montante],Base[Fornecedor],$A12&"",Base[Ano],F$4) | G12: =SUMIFS(Base[Montante],Base[Fornecedor],$A12&"",Base[Ano],G$4) | H12: =SUMIFS(Base[Montante],Base[Fornecedor],$A12&"",Base[Ano],H$4) | I12: =SUMIFS(Base[Montante],Base[Fornecedor],$A12&"",Base[Ano],I$4) | J12: =SUMIFS(Base[Montante],Base[Fornecedor],$A12&"",Base[Ano],J$4) | K12: =SUM(D12:J12)
A13: 103886 | B13: FEDERAL EXPRESS CORPORATION | C13: =IFERROR(INDEX(DePara[Categoria],MATCH(TEXT(A13,"0"),DePara[Fornecedor_txt],0)),"(sem categoria)") | D13: =SUMIFS(Base[Montante],Base[Fornecedor],$A13&"",Base[Ano],D$4) | E13: =SUMIFS(Base[Montante],Base[Fornecedor],$A13&"",Base[Ano],E$4) | F13: =SUMIFS(Base[Montante],Base[Fornecedor],$A13&"",Base[Ano],F$4) | G13: =SUMIFS(Base[Montante],Base[Fornecedor],$A13&"",Base[Ano],G$4) | H13: =SUMIFS(Base[Montante],Base[Fornecedor],$A13&"",Base[Ano],H$4) | I13: =SUMIFS(Base[Montante],Base[Fornecedor],$A13&"",Base[Ano],I$4) | J13: =SUMIFS(Base[Montante],Base[Fornecedor],$A13&"",Base[Ano],J$4) | K13: =SUM(D13:J13)
A14: 101777 | B14: INGRAM MICRO BRASIL LTDA | C14: =IFERROR(INDEX(DePara[Categoria],MATCH(TEXT(A14,"0"),DePara[Fornecedor_txt],0)),"(sem categoria)") | D14: =SUMIFS(Base[Montante],Base[Fornecedor],$A14&"",Base[Ano],D$4) | E14: =SUMIFS(Base[Montante],Base[Fornecedor],$A14&"",Base[Ano],E$4) | F14: =SUMIFS(Base[Montante],Base[Fornecedor],$A14&"",Base[Ano],F$4) | G14: =SUMIFS(Base[Montante],Base[Fornecedor],$A14&"",Base[Ano],G$4) | H14: =SUMIFS(Base[Montante],Base[Fornecedor],$A14&"",Base[Ano],H$4) | I14: =SUMIFS(Base[Montante],Base[Fornecedor],$A14&"",Base[Ano],I$4) | J14: =SUMIFS(Base[Montante],Base[Fornecedor],$A14&"",Base[Ano],J$4) | K14: =SUM(D14:J14)
A15: 102099 | B15: INGRAM MICRO BRASIL LTDA | C15: =IFERROR(INDEX(DePara[Categoria],MATCH(TEXT(A15,"0"),DePara[Fornecedor_txt],0)),"(sem categoria)") | D15: =SUMIFS(Base[Montante],Base[Fornecedor],$A15&"",Base[Ano],D$4) | E15: =SUMIFS(Base[Montante],Base[Fornecedor],$A15&"",Base[Ano],E$4) | F15: =SUMIFS(Base[Montante],Base[Fornecedor],$A15&"",Base[Ano],F$4) | G15: =SUMIFS(Base[Montante],Base[Fornecedor],$A15&"",Base[Ano],G$4) | H15: =SUMIFS(Base[Montante],Base[Fornecedor],$A15&"",Base[Ano],H$4) | I15: =SUMIFS(Base[Montante],Base[Fornecedor],$A15&"",Base[Ano],I$4) | J15: =SUMIFS(Base[Montante],Base[Fornecedor],$A15&"",Base[Ano],J$4) | K15: =SUM(D15:J15)
A16: 101611 | B16: SECRETARIA DA FAZENDA BAHIA | C16: =IFERROR(INDEX(DePara[Categoria],MATCH(TEXT(A16,"0"),DePara[Fornecedor_txt],0)),"(sem categoria)") | D16: =SUMIFS(Base[Montante],Base[Fornecedor],$A16&"",Base[Ano],D$4) | E16: =SUMIFS(Base[Montante],Base[Fornecedor],$A16&"",Base[Ano],E$4) | F16: =SUMIFS(Base[Montante],Base[Fornecedor],$A16&"",Base[Ano],F$4) | G16: =SUMIFS(Base[Montante],Base[Fornecedor],$A16&"",Base[Ano],G$4) | H16: =SUMIFS(Base[Montante],Base[Fornecedor],$A16&"",Base[Ano],H$4) | I16: =SUMIFS(Base[Montante],Base[Fornecedor],$A16&"",Base[Ano],I$4) | J16: =SUMIFS(Base[Montante],Base[Fornecedor],$A16&"",Base[Ano],J$4) | K16: =SUM(D16:J16)
... A28: 101178 | B28: ACTUANT GMBH | C28: =IFERROR(INDEX(DePara[Categoria],MATCH(TEXT(A28,"0"),DePara[Fornecedor_txt],0)),"(sem categoria)") | D28: =SUMIFS(Base[Montante],Base[Fornecedor],$A28&"",Base[Ano],D$4) | E28: =SUMIFS(Base[Montante],Base[Fornecedor],$A28&"",Base[Ano],E$4) | F28: =SUMIFS(Base[Montante],Base[Fornecedor],$A28&"",Base[Ano],F$4) | G28: =SUMIFS(Base[Montante],Base[Fornecedor],$A28&"",Base[Ano],G$4) | H28: =SUMIFS(Base[Montante],Base[Fornecedor],$A28&"",Base[Ano],H$4) | I28: =SUMIFS(Base[Montante],Base[Fornecedor],$A28&"",Base[Ano],I$4) | J28: =SUMIFS(Base[Montante],Base[Fornecedor],$A28&"",Base[Ano],J$4) | K28: =SUM(D28:J28)
A29: EM000826 | B29: ADALBERTO COELHO DE SOUSA | C29: =IFERROR(INDEX(DePara[Categoria],MATCH(TEXT(A29,"0"),DePara[Fornecedor_txt],0)),"(sem categoria)") | D29: =SUMIFS(Base[Montante],Base[Fornecedor],$A29&"",Base[Ano],D$4) | E29: =SUMIFS(Base[Montante],Base[Fornecedor],$A29&"",Base[Ano],E$4) | F29: =SUMIFS(Base[Montante],Base[Fornecedor],$A29&"",Base[Ano],F$4) | G29: =SUMIFS(Base[Montante],Base[Fornecedor],$A29&"",Base[Ano],G$4) | H29: =SUMIFS(Base[Montante],Base[Fornecedor],$A29&"",Base[Ano],H$4) | I29: =SUMIFS(Base[Montante],Base[Fornecedor],$A29&"",Base[Ano],I$4) | J29: =SUMIFS(Base[Montante],Base[Fornecedor],$A29&"",Base[Ano],J$4) | K29: =SUM(D29:J29)
A30: 102057 | B30: AERIS INDUSTRIA E COM EQUI GERACAO | C30: =IFERROR(INDEX(DePara[Categoria],MATCH(TEXT(A30,"0"),DePara[Fornecedor_txt],0)),"(sem categoria)") | D30: =SUMIFS(Base[Montante],Base[Fornecedor],$A30&"",Base[Ano],D$4) | E30: =SUMIFS(Base[Montante],Base[Fornecedor],$A30&"",Base[Ano],E$4) | F30: =SUMIFS(Base[Montante],Base[Fornecedor],$A30&"",Base[Ano],F$4) | G30: =SUMIFS(Base[Montante],Base[Fornecedor],$A30&"",Base[Ano],G$4) | H30: =SUMIFS(Base[Montante],Base[Fornecedor],$A30&"",Base[Ano],H$4) | I30: =SUMIFS(Base[Montante],Base[Fornecedor],$A30&"",Base[Ano],I$4) | J30: =SUMIFS(Base[Montante],Base[Fornecedor],$A30&"",Base[Ano],J$4) | K30: =SUM(D30:J30)
A31: 101043 | B31: AEROPORTO BRASIL VIRACOPOS SA | C31: =IFERROR(INDEX(DePara[Categoria],MATCH(TEXT(A31,"0"),DePara[Fornecedor_txt],0)),"(sem categoria)") | D31: =SUMIFS(Base[Montante],Base[Fornecedor],$A31&"",Base[Ano],D$4) | E31: =SUMIFS(Base[Montante],Base[Fornecedor],$A31&"",Base[Ano],E$4) | F31: =SUMIFS(Base[Montante],Base[Fornecedor],$A31&"",Base[Ano],F$4) | G31: =SUMIFS(Base[Montante],Base[Fornecedor],$A31&"",Base[Ano],G$4) | H31: =SUMIFS(Base[Montante],Base[Fornecedor],$A31&"",Base[Ano],H$4) | I31: =SUMIFS(Base[Montante],Base[Fornecedor],$A31&"",Base[Ano],I$4) | J31: =SUMIFS(Base[Montante],Base[Fornecedor],$A31&"",Base[Ano],J$4) | K31: =SUM(D31:J31)
A32: 101494 | B32: AG SOLVE MONITORAMENTO AMBIENTAL LT | C32: =IFERROR(INDEX(DePara[Categoria],MATCH(TEXT(A32,"0"),DePara[Fornecedor_txt],0)),"(sem categoria)") | D32: =SUMIFS(Base[Montante],Base[Fornecedor],$A32&"",Base[Ano],D$4) | E32: =SUMIFS(Base[Montante],Base[Fornecedor],$A32&"",Base[Ano],E$4) | F32: =SUMIFS(Base[Montante],Base[Fornecedor],$A32&"",Base[Ano],F$4) | G32: =SUMIFS(Base[Montante],Base[Fornecedor],$A32&"",Base[Ano],G$4) | H32: =SUMIFS(Base[Montante],Base[Fornecedor],$A32&"",Base[Ano],H$4) | I32: =SUMIFS(Base[Montante],Base[Fornecedor],$A32&"",Base[Ano],I$4) | J32: =SUMIFS(Base[Montante],Base[Fornecedor],$A32&"",Base[Ano],J$4) | K32: =SUM(D32:J32)
A33: 101254 | B33: AGENCIA BRASILEIRA DE METEOROLOGIA | C33: =IFERROR(INDEX(DePara[Categoria],MATCH(TEXT(A33,"0"),DePara[Fornecedor_txt],0)),"(sem categoria)") | D33: =SUMIFS(Base[Montante],Base[Fornecedor],$A33&"",Base[Ano],D$4) | E33: =SUMIFS(Base[Montante],Base[Fornecedor],$A33&"",Base[Ano],E$4) | F33: =SUMIFS(Base[Montante],Base[Fornecedor],$A33&"",Base[Ano],F$4) | G33: =SUMIFS(Base[Montante],Base[Fornecedor],$A33&"",Base[Ano],G$4) | H33: =SUMIFS(Base[Montante],Base[Fornecedor],$A33&"",Base[Ano],H$4) | I33: =SUMIFS(Base[Montante],Base[Fornecedor],$A33&"",Base[Ano],I$4) | J33: =SUMIFS(Base[Montante],Base[Fornecedor],$A33&"",Base[Ano],J$4) | K33: =SUM(D33:J33)
A34: 101688 | B34: AGIS EQUIPAMENTOS E SERVIÇOS DE INFORMATICA LTDA | C34: =IFERROR(INDEX(DePara[Categoria],MATCH(TEXT(A34,"0"),DePara[Fornecedor_txt],0)),"(sem categoria)") | D34: =SUMIFS(Base[Montante],Base[Fornecedor],$A34&"",Base[Ano],D$4) | E34: =SUMIFS(Base[Montante],Base[Fornecedor],$A34&"",Base[Ano],E$4) | F34: =SUMIFS(Base[Montante],Base[Fornecedor],$A34&"",Base[Ano],F$4) | G34: =SUMIFS(Base[Montante],Base[Fornecedor],$A34&"",Base[Ano],G$4) | H34: =SUMIFS(Base[Montante],Base[Fornecedor],$A34&"",Base[Ano],H$4) | I34: =SUMIFS(Base[Montante],Base[Fornecedor],$A34&"",Base[Ano],I$4) | J34: =SUMIFS(Base[Montante],Base[Fornecedor],$A34&"",Base[Ano],J$4) | K34: =SUM(D34:J34)
A35: 100183 | B35: AGL TRANSPORTES INTERNACIONAIS LTDA | C35: =IFERROR(INDEX(DePara[Categoria],MATCH(TEXT(A35,"0"),DePara[Fornecedor_txt],0)),"(sem categoria)") | D35: =SUMIFS(Base[Montante],Base[Fornecedor],$A35&"",Base[Ano],D$4) | E35: =SUMIFS(Base[Montante],Base[Fornecedor],$A35&"",Base[Ano],E$4) | F35: =SUMIFS(Base[Montante],Base[Fornecedor],$A35&"",Base[Ano],F$4) | G35: =SUMIFS(Base[Montante],Base[Fornecedor],$A35&"",Base[Ano],G$4) | H35: =SUMIFS(Base[Montante],Base[Fornecedor],$A35&"",Base[Ano],H$4) | I35: =SUMIFS(Base[Montante],Base[Fornecedor],$A35&"",Base[Ano],I$4) | J35: =SUMIFS(Base[Montante],Base[Fornecedor],$A35&"",Base[Ano],J$4) | K35: =SUM(D35:J35)
A36: 101222 | B36: AGROPECUARIA CANOA MIRIM SA | C36: =IFERROR(INDEX(DePara[Categoria],MATCH(TEXT(A36,"0"),DePara[Fornecedor_txt],0)),"(sem categoria)") | D36: =SUMIFS(Base[Montante],Base[Fornecedor],$A36&"",Base[Ano],D$4) | E36: =SUMIFS(Base[Montante],Base[Fornecedor],$A36&"",Base[Ano],E$4) | F36: =SUMIFS(Base[Montante],Base[Fornecedor],$A36&"",Base[Ano],F$4) | G36: =SUMIFS(Base[Montante],Base[Fornecedor],$A36&"",Base[Ano],G$4) | H36: =SUMIFS(Base[Montante],Base[Fornecedor],$A36&"",Base[Ano],H$4) | I36: =SUMIFS(Base[Montante],Base[Fornecedor],$A36&"",Base[Ano],I$4) | J36: =SUMIFS(Base[Montante],Base[Fornecedor],$A36&"",Base[Ano],J$4) | K36: =SUM(D36:J36)
A37: 103745 | B37: AIR LIDER COMERCIO E TRANSPORTE DE | C37: =IFERROR(INDEX(DePara[Categoria],MATCH(TEXT(A37,"0"),DePara[Fornecedor_txt],0)),"(sem categoria)") | D37: =SUMIFS(Base[Montante],Base[Fornecedor],$A37&"",Base[Ano],D$4) | E37: =SUMIFS(Base[Montante],Base[Fornecedor],$A37&"",Base[Ano],E$4) | F37: =SUMIFS(Base[Montante],Base[Fornecedor],$A37&"",Base[Ano],F$4) | G37: =SUMIFS(Base[Montante],Base[Fornecedor],$A37&"",Base[Ano],G$4) | H37: =SUMIFS(Base[Montante],Base[Fornecedor],$A37&"",Base[Ano],H$4) | I37: =SUMIFS(Base[Montante],Base[Fornecedor],$A37&"",Base[Ano],I$4) | J37: =SUMIFS(Base[Montante],Base[Fornecedor],$A37&"",Base[Ano],J$4) | K37: =SUM(D37:J37)
A38: 115200 | B38: AIR LIDER GROUP COMERCIO DE GASES | C38: =IFERROR(INDEX(DePara[Categoria],MATCH(TEXT(A38,"0"),DePara[Fornecedor_txt],0)),"(sem categoria)") | D38: =SUMIFS(Base[Montante],Base[Fornecedor],$A38&"",Base[Ano],D$4) | E38: =SUMIFS(Base[Montante],Base[Fornecedor],$A38&"",Base[Ano],E$4) | F38: =SUMIFS(Base[Montante],Base[Fornecedor],$A38&"",Base[Ano],F$4) | G38: =SUMIFS(Base[Montante],Base[Fornecedor],$A38&"",Base[Ano],G$4) | H38: =SUMIFS(Base[Montante],Base[Fornecedor],$A38&"",Base[Ano],H$4) | I38: =SUMIFS(Base[Montante],Base[Fornecedor],$A38&"",Base[Ano],I$4) | J38: =SUMIFS(Base[Montante],Base[Fornecedor],$A38&"",Base[Ano],J$4) | K38: =SUM(D38:J38)
A39: EM000147 | B39: AIRTON SHARLES E SILVA PESSOA | C39: =IFERROR(INDEX(DePara[Categoria],MATCH(TEXT(A39,"0"),DePara[Fornecedor_txt],0)),"(sem categoria)") | D39: =SUMIFS(Base[Montante],Base[Fornecedor],$A39&"",Base[Ano],D$4) | E39: =SUMIFS(Base[Montante],Base[Fornecedor],$A39&"",Base[Ano],E$4) | F39: =SUMIFS(Base[Montante],Base[Fornecedor],$A39&"",Base[Ano],F$4) | G39: =SUMIFS(Base[Montante],Base[Fornecedor],$A39&"",Base[Ano],G$4) | H39: =SUMIFS(Base[Montante],Base[Fornecedor],$A39&"",Base[Ano],H$4) | I39: =SUMIFS(Base[Montante],Base[Fornecedor],$A39&"",Base[Ano],I$4) | J39: =SUMIFS(Base[Montante],Base[Fornecedor],$A39&"",Base[Ano],J$4) | K39: =SUM(D39:J39)
A40: EM000542 | B40: AKIM FELTRIM CARDOSO | C40: =IFERROR(INDEX(DePara[Categoria],MATCH(TEXT(A40,"0"),DePara[Fornecedor_txt],0)),"(sem categoria)") | D40: =SUMIFS(Base[Montante],Base[Fornecedor],$A40&"",Base[Ano],D$4) | E40: =SUMIFS(Base[Montante],Base[Fornecedor],$A40&"",Base[Ano],E$4) | F40: =SUMIFS(Base[Montante],Base[Fornecedor],$A40&"",Base[Ano],F$4) | G40: =SUMIFS(Base[Montante],Base[Fornecedor],$A40&"",Base[Ano],G$4) | H40: =SUMIFS(Base[Montante],Base[Fornecedor],$A40&"",Base[Ano],H$4) | I40: =SUMIFS(Base[Montante],Base[Fornecedor],$A40&"",Base[Ano],I$4) | J40: =SUMIFS(Base[Montante],Base[Fornecedor],$A40&"",Base[Ano],J$4) | K40: =SUM(D40:J40)
A41: 101226 | B41: AL WIND SOLUCOES LTDA | C41: =IFERROR(INDEX(DePara[Categoria],MATCH(TEXT(A41,"0"),DePara[Fornecedor_txt],0)),"(sem categoria)") | D41: =SUMIFS(Base[Montante],Base[Fornecedor],$A41&"",Base[Ano],D$4) | E41: =SUMIFS(Base[Montante],Base[Fornecedor],$A41&"",Base[Ano],E$4) | F41: =SUMIFS(Base[Montante],Base[Fornecedor],$A41&"",Base[Ano],F$4) | G41: =SUMIFS(Base[Montante],Base[Fornecedor],$A41&"",Base[Ano],G$4) | H41: =SUMIFS(Base[Montante],Base[Fornecedor],$A41&"",Base[Ano],H$4) | I41: =SUMIFS(Base[Montante],Base[Fornecedor],$A41&"",Base[Ano],I$4) | J41: =SUMIFS(Base[Montante],Base[Fornecedor],$A41&"",Base[Ano],J$4) | K41: =SUM(D41:J41)
A42: EM000171 | B42: ALESSANDRA RAFFO SCHNEIDER | C42: =IFERROR(INDEX(DePara[Categoria],MATCH(TEXT(A42,"0"),DePara[Fornecedor_txt],0)),"(sem categoria)") | D42: =SUMIFS(Base[Montante],Base[Fornecedor],$A42&"",Base[Ano],D$4) | E42: =SUMIFS(Base[Montante],Base[Fornecedor],$A42&"",Base[Ano],E$4) | F42: =SUMIFS(Base[Montante],Base[Fornecedor],$A42&"",Base[Ano],F$4) | G42: =SUMIFS(Base[Montante],Base[Fornecedor],$A42&"",Base[Ano],G$4) | H42: =SUMIFS(Base[Montante],Base[Fornecedor],$A42&"",Base[Ano],H$4) | I42: =SUMIFS(Base[Montante],Base[Fornecedor],$A42&"",Base[Ano],I$4) | J42: =SUMIFS(Base[Montante],Base[Fornecedor],$A42&"",Base[Ano],J$4) | K42: =SUM(D42:J42)
A43: EM000018 | B43: ALESSANDRO SANTANA CORTES | C43: =IFERROR(INDEX(DePara[Categoria],MATCH(TEXT(A43,"0"),DePara[Fornecedor_txt],0)),"(sem categoria)") | D43: =SUMIFS(Base[Montante],Base[Fornecedor],$A43&"",Base[Ano],D$4) | E43: =SUMIFS(Base[Montante],Base[Fornecedor],$A43&"",Base[Ano],E$4) | F43: =SUMIFS(Base[Montante],Base[Fornecedor],$A43&"",Base[Ano],F$4) | G43: =SUMIFS(Base[Montante],Base[Fornecedor],$A43&"",Base[Ano],G$4) | H43: =SUMIFS(Base[Montante],Base[Fornecedor],$A43&"",Base[Ano],H$4) | I43: =SUMIFS(Base[Montante],Base[Fornecedor],$A43&"",Base[Ano],I$4) | J43: =SUMIFS(Base[Montante],Base[Fornecedor],$A43&"",Base[Ano],J$4) | K43: =SUM(D43:J43)
A44: EM000451 | B44: ALEX DA SILVA CONCEIÇÃO | C44: =IFERROR(INDEX(DePara[Categoria],MATCH(TEXT(A44,"0"),DePara[Fornecedor_txt],0)),"(sem categoria)") | D44: =SUMIFS(Base[Montante],Base[Fornecedor],$A44&"",Base[Ano],D$4) | E44: =SUMIFS(Base[Montante],Base[Fornecedor],$A44&"",Base[Ano],E$4) | F44: =SUMIFS(Base[Montante],Base[Fornecedor],$A44&"",Base[Ano],F$4) | G44: =SUMIFS(Base[Montante],Base[Fornecedor],$A44&"",Base[Ano],G$4) | H44: =SUMIFS(Base[Montante],Base[Fornecedor],$A44&"",Base[Ano],H$4) | I44: =SUMIFS(Base[Montante],Base[Fornecedor],$A44&"",Base[Ano],I$4) | J44: =SUMIFS(Base[Montante],Base[Fornecedor],$A44&"",Base[Ano],J$4) | K44: =SUM(D44:J44)
A45: EM000035 | B45: ALEXANDRE SILVEIRA TRINDADE | C45: =IFERROR(INDEX(DePara[Categoria],MATCH(TEXT(A45,"0"),DePara[Fornecedor_txt],0)),"(sem categoria)") | D45: =SUMIFS(Base[Montante],Base[Fornecedor],$A45&"",Base[Ano],D$4) | E45: =SUMIFS(Base[Montante],Base[Fornecedor],$A45&"",Base[Ano],E$4) | F45: =SUMIFS(Base[Montante],Base[Fornecedor],$A45&"",Base[Ano],F$4) | G45: =SUMIFS(Base[Montante],Base[Fornecedor],$A45&"",Base[Ano],G$4) | H45: =SUMIFS(Base[Montante],Base[Fornecedor],$A45&"",Base[Ano],H$4) | I45: =SUMIFS(Base[Montante],Base[Fornecedor],$A45&"",Base[Ano],I$4) | J45: =SUMIFS(Base[Montante],Base[Fornecedor],$A45&"",Base[Ano],J$4) | K45: =SUM(D45:J45)
A46: EM000549 | B46: ALISSON ALEXANDRE CARVALHO ARAUJO | C46: =IFERROR(INDEX(DePara[Categoria],MATCH(TEXT(A46,"0"),DePara[Fornecedor_txt],0)),"(sem categoria)") | D46: =SUMIFS(Base[Montante],Base[Fornecedor],$A46&"",Base[Ano],D$4) | E46: =SUMIFS(Base[Montante],Base[Fornecedor],$A46&"",Base[Ano],E$4) | F46: =SUMIFS(Base[Montante],Base[Fornecedor],$A46&"",Base[Ano],F$4) | G46: =SUMIFS(Base[Montante],Base[Fornecedor],$A46&"",Base[Ano],G$4) | H46: =SUMIFS(Base[Montante],Base[Fornecedor],$A46&"",Base[Ano],H$4) | I46: =SUMIFS(Base[Montante],Base[Fornecedor],$A46&"",Base[Ano],I$4) | J46: =SUMIFS(Base[Montante],Base[Fornecedor],$A46&"",Base[Ano],J$4) | K46: =SUM(D46:J46)
A47: 101133 | B47: ALLIANZ SEGUROS SA USD | C47: =IFERROR(INDEX(DePara[Categoria],MATCH(TEXT(A47,"0"),DePara[Fornecedor_txt],0)),"(sem categoria)") | D47: =SUMIFS(Base[Montante],Base[Fornecedor],$A47&"",Base[Ano],D$4) | E47: =SUMIFS(Base[Montante],Base[Fornecedor],$A47&"",Base[Ano],E$4) | F47: =SUMIFS(Base[Montante],Base[Fornecedor],$A47&"",Base[Ano],F$4) | G47: =SUMIFS(Base[Montante],Base[Fornecedor],$A47&"",Base[Ano],G$4) | H47: =SUMIFS(Base[Montante],Base[Fornecedor],$A47&"",Base[Ano],H$4) | I47: =SUMIFS(Base[Montante],Base[Fornecedor],$A47&"",Base[Ano],I$4) | J47: =SUMIFS(Base[Montante],Base[Fornecedor],$A47&"",Base[Ano],J$4) | K47: =SUM(D47:J47)
A48: EM000511 | B48: ALLISON DE OLIVEIRA COSTA | C48: =IFERROR(INDEX(DePara[Categoria],MATCH(TEXT(A48,"0"),DePara[Fornecedor_txt],0)),"(sem categoria)") | D48: =SUMIFS(Base[Montante],Base[Fornecedor],$A48&"",Base[Ano],D$4) | E48: =SUMIFS(Base[Montante],Base[Fornecedor],$A48&"",Base[Ano],E$4) | F48: =SUMIFS(Base[Montante],Base[Fornecedor],$A48&"",Base[Ano],F$4) | G48: =SUMIFS(Base[Montante],Base[Fornecedor],$A48&"",Base[Ano],G$4) | H48: =SUMIFS(Base[Montante],Base[Fornecedor],$A48&"",Base[Ano],H$4) | I48: =SUMIFS(Base[Montante],Base[Fornecedor],$A48&"",Base[Ano],I$4) | J48: =SUMIFS(Base[Montante],Base[Fornecedor],$A48&"",Base[Ano],J$4) | K48: =SUM(D48:J48)
A49: EM000262 | B49: ALLYSSON LAURENTINO DE MELO RAMOS | C49: =IFERROR(INDEX(DePara[Categoria],MATCH(TEXT(A49,"0"),DePara[Fornecedor_txt],0)),"(sem categoria)") | D49: =SUMIFS(Base[Montante],Base[Fornecedor],$A49&"",Base[Ano],D$4) | E49: =SUMIFS(Base[Montante],Base[Fornecedor],$A49&"",Base[Ano],E$4) | F49: =SUMIFS(Base[Montante],Base[Fornecedor],$A49&"",Base[Ano],F$4) | G49: =SUMIFS(Base[Montante],Base[Fornecedor],$A49&"",Base[Ano],G$4) | H49: =SUMIFS(Base[Montante],Base[Fornecedor],$A49&"",Base[Ano],H$4) | I49: =SUMIFS(Base[Montante],Base[Fornecedor],$A49&"",Base[Ano],I$4) | J49: =SUMIFS(Base[Montante],Base[Fornecedor],$A49&"",Base[Ano],J$4) | K49: =SUM(D49:J49)
A50: 101937 | B50: ALONSO DOLDAN INGENIERIA Y SERVICIO | C50: =IFERROR(INDEX(DePara[Categoria],MATCH(TEXT(A50,"0"),DePara[Fornecedor_txt],0)),"(sem categoria)") | D50: =SUMIFS(Base[Montante],Base[Fornecedor],$A50&"",Base[Ano],D$4) | E50: =SUMIFS(Base[Montante],Base[Fornecedor],$A50&"",Base[Ano],E$4) | F50: =SUMIFS(Base[Montante],Base[Fornecedor],$A50&"",Base[Ano],F$4) | G50: =SUMIFS(Base[Montante],Base[Fornecedor],$A50&"",Base[Ano],G$4) | H50: =SUMIFS(Base[Montante],Base[Fornecedor],$A50&"",Base[Ano],H$4) | I50: =SUMIFS(Base[Montante],Base[Fornecedor],$A50&"",Base[Ano],I$4) | J50: =SUMIFS(Base[Montante],Base[Fornecedor],$A50&"",Base[Ano],J$4) | K50: =SUM(D50:J50)
A51: 101340 | B51: ALS TRIBOLOGY BRASIL ANALISE DE FLU | C51: =IFERROR(INDEX(DePara[Categoria],MATCH(TEXT(A51,"0"),DePara[Fornecedor_txt],0)),"(sem categoria)") | D51: =SUMIFS(Base[Montante],Base[Fornecedor],$A51&"",Base[Ano],D$4) | E51: =SUMIFS(Base[Montante],Base[Fornecedor],$A51&"",Base[Ano],E$4) | F51: =SUMIFS(Base[Montante],Base[Fornecedor],$A51&"",Base[Ano],F$4) | G51: =SUMIFS(Base[Montante],Base[Fornecedor],$A51&"",Base[Ano],G$4) | H51: =SUMIFS(Base[Montante],Base[Fornecedor],$A51&"",Base[Ano],H$4) | I51: =SUMIFS(Base[Montante],Base[Fornecedor],$A51&"",Base[Ano],I$4) | J51: =SUMIFS(Base[Montante],Base[Fornecedor],$A51&"",Base[Ano],J$4) | K51: =SUM(D51:J51)
...

Sheet Detalhe
A1: DRILL-DOWN
A2: Composicao de qualquer saldo
A3: Use as setas de filtro no cabecalho da tabela abaixo para filtrar por Fornecedor, Categoria, Conta ou Ano — filtro nativo do Excel, 100% compativel.
A5: Fornecedor | B5: Nome do fornecedor | C5: Conta | D5: Categoria | E5: Documento | F5: Referencia | G5: Tipo doc | H5: Montante | I5: Data documento | J5: Data vencimento | K5: Texto
A6: IC1000 | B6: NORDEX ENERGY SE & CO KG | C6: 2122100000 | D6: Intercompany | E6: 1008418 | G6: AB | H6: 33462.83 | I6: 45227 | J6: 45227 | K6: Clearing document NORDEX ENERGY SE & CO. KG
A7: IC4420 | B7: NORDEX ENERGY SPAIN S A U | C7: 2122100000 | D7: Intercompany | E7: 1008419 | G7: AB | H7: 93546.45 | I7: 45227 | J7: 45227 | K7: Clearing document NORDEX ENERGY SPAIN S.A.U.
